<?xml version="1.0"?>
<robot xmlns:xacro="http://www.ros.org/wiki/xacro">

  <!-- Xacro properties for wheel dimensions -->
  <xacro:property name="wheel_radius" value="0.0352"/>
  <xacro:property name="wheel_width" value="0.0206"/>

  <!-- Drive Wheel Macro -->
  <xacro:macro name="drive_wheel" params="prefix parent_link *origin">

    <!-- Wheel Link -->
    <link name="${prefix}_wheel">
      <visual>
        <origin xyz="0 0 0" rpy="0 1.5707 1.5707"/>
        <geometry>
          <cylinder radius="${wheel_radius}" length="${wheel_width}"/>
        </geometry>
        <material name="black"/>
      </visual>

      <collision>
        <origin xyz="0 0 0" rpy="0 1.5707 1.5707"/>
        <geometry>
          <cylinder radius="${wheel_radius}" length="${wheel_width}"/>
        </geometry>
      </collision>

      <inertial>
        <origin xyz="0 0 0" rpy="0 1.5707 1.5707"/>
        <mass value="0.5"/>
        <inertia ixx="0.000173" ixy="0.0" ixz="0.0" iyy="0.000173" iyz="0.0" izz="0.00031"/>
      </inertial>
    </link>

    <!-- Wheel Joint -->
    <joint name="${prefix}_wheel_joint" type="continuous">
      <xacro:insert_block name="origin"/>
      <parent link="${parent_link}"/>
      <child link="${prefix}_wheel"/>
      <axis rpy="0 0 0" xyz="0 1 0"/>
      <limit effort="10000" velocity="1000"/>
      <joint_properties damping="1.0" friction="1.0"/>
    </joint>

    <!-- Gazebo Properties for Wheel -->
    <gazebo reference="${prefix}_wheel">
      <material>Gazebo/Black</material>
      <kp>1000000000000000000000000000.0</kp>
      <kd>1000000000000000000000000000.0</kd>
      <mu1>10.0</mu1>
      <mu2>10.0</mu2>
    </gazebo>

  </xacro:macro>

</robot>
